WARNING 2018-08-22 18:11:55,802 /home/python/.virtualenvs/dailyfresh/local/lib/python3.5/site-packages/django/core/handlers/base.py 170: Not Found: /
WARNING 2018-08-22 18:11:56,002 /home/python/.virtualenvs/dailyfresh/local/lib/python3.5/site-packages/django/core/handlers/base.py 170: Not Found: /favicon.ico
ERROR 2018-08-22 18:12:00,713 /home/python/Desktop/Hellocial/Hellocial_0_1/apps/users/views.py 1244: Error 111 connecting to 127.0.0.1:6379. Connection refused.
ERROR 2018-08-22 18:12:17,442 /home/python/Desktop/Hellocial/Hellocial_0_1/apps/users/views.py 1244: Error 111 connecting to 127.0.0.1:6379. Connection refused.
ERROR 2018-08-22 18:12:19,034 /home/python/Desktop/Hellocial/Hellocial_0_1/apps/users/views.py 1244: Error 111 connecting to 127.0.0.1:6379. Connection refused.
ERROR 2018-08-22 18:12:51,344 /home/python/Desktop/Hellocial/Hellocial_0_1/apps/users/views.py 1244: Error 111 connecting to 127.0.0.1:6379. Connection refused.
ERROR 2018-08-22 18:12:52,435 /home/python/Desktop/Hellocial/Hellocial_0_1/apps/users/views.py 1244: Error 111 connecting to 127.0.0.1:6379. Connection refused.
ERROR 2018-08-22 18:13:54,442 /home/python/Desktop/Hellocial/Hellocial_0_1/apps/users/views.py 1244: Error 111 connecting to 127.0.0.1:6379. Connection refused.
WARNING 2018-08-22 18:14:53,473 /home/python/Desktop/Hellocial/Hellocial_0_1/apps/users/views.py 1036: 用户缺乏隶属信息
ERROR 2018-08-22 18:15:00,514 /home/python/.virtualenvs/dailyfresh/local/lib/python3.5/site-packages/django/core/handlers/base.py 256: Internal Server Error: /users/slaves
Traceback (most recent call last):
  File "/home/python/.virtualenvs/dailyfresh/local/lib/python3.5/site-packages/django/db/models/options.py", line 552, in get_field
    return self.fields_map[field_name]
KeyError: 'user'

During handling of the above exception, another exception occurred:

Traceback (most recent call last):
  File "/home/python/.virtualenvs/dailyfresh/local/lib/python3.5/site-packages/django/db/models/sql/query.py", line 1362, in names_to_path
    field = opts.get_field(name)
  File "/home/python/.virtualenvs/dailyfresh/local/lib/python3.5/site-packages/django/db/models/options.py", line 554, in get_field
    raise FieldDoesNotExist('%s has no field named %r' % (self.object_name, field_name))
django.core.exceptions.FieldDoesNotExist: MemberShip has no field named 'user'

During handling of the above exception, another exception occurred:

Traceback (most recent call last):
  File "/home/python/.virtualenvs/dailyfresh/local/lib/python3.5/site-packages/django/core/handlers/base.py", line 132, in get_response
    response = wrapped_callback(request, *callback_args, **callback_kwargs)
  File "/home/python/.virtualenvs/dailyfresh/local/lib/python3.5/site-packages/django/contrib/auth/decorators.py", line 22, in _wrapped_view
    return view_func(request, *args, **kwargs)
  File "/home/python/.virtualenvs/dailyfresh/local/lib/python3.5/site-packages/django/contrib/auth/decorators.py", line 22, in _wrapped_view
    return view_func(request, *args, **kwargs)
  File "/home/python/.virtualenvs/dailyfresh/local/lib/python3.5/site-packages/django/views/generic/base.py", line 71, in view
    return self.dispatch(request, *args, **kwargs)
  File "/home/python/Desktop/Hellocial/Hellocial_0_1/utils/mixin.py", line 93, in dispatch
    return handler(request, *args, **kwargs)
  File "/home/python/Desktop/Hellocial/Hellocial_0_1/apps/users/views.py", line 330, in get
    for slave in rel_page:
  File "/home/python/.virtualenvs/dailyfresh/lib/python3.5/_collections_abc.py", line 815, in __iter__
    v = self[i]
  File "/home/python/.virtualenvs/dailyfresh/local/lib/python3.5/site-packages/django/core/paginator.py", line 125, in __getitem__
    self.object_list = list(self.object_list)
  File "/home/python/.virtualenvs/dailyfresh/local/lib/python3.5/site-packages/django/db/models/query.py", line 162, in __iter__
    self._fetch_all()
  File "/home/python/.virtualenvs/dailyfresh/local/lib/python3.5/site-packages/django/db/models/query.py", line 965, in _fetch_all
    self._result_cache = list(self.iterator())
  File "/home/python/.virtualenvs/dailyfresh/local/lib/python3.5/site-packages/django/db/models/query.py", line 238, in iterator
    results = compiler.execute_sql()
  File "/home/python/.virtualenvs/dailyfresh/local/lib/python3.5/site-packages/django/db/models/sql/compiler.py", line 829, in execute_sql
    sql, params = self.as_sql()
  File "/home/python/.virtualenvs/dailyfresh/local/lib/python3.5/site-packages/django/db/models/sql/compiler.py", line 378, in as_sql
    extra_select, order_by, group_by = self.pre_sql_setup()
  File "/home/python/.virtualenvs/dailyfresh/local/lib/python3.5/site-packages/django/db/models/sql/compiler.py", line 49, in pre_sql_setup
    order_by = self.get_order_by()
  File "/home/python/.virtualenvs/dailyfresh/local/lib/python3.5/site-packages/django/db/models/sql/compiler.py", line 286, in get_order_by
    field, self.query.get_meta(), default_order=asc))
  File "/home/python/.virtualenvs/dailyfresh/local/lib/python3.5/site-packages/django/db/models/sql/compiler.py", line 558, in find_ordering_name
    field, targets, alias, joins, path, opts = self._setup_joins(pieces, opts, alias)
  File "/home/python/.virtualenvs/dailyfresh/local/lib/python3.5/site-packages/django/db/models/sql/compiler.py", line 591, in _setup_joins
    pieces, opts, alias)
  File "/home/python/.virtualenvs/dailyfresh/local/lib/python3.5/site-packages/django/db/models/sql/query.py", line 1466, in setup_joins
    names, opts, allow_many, fail_on_missing=True)
  File "/home/python/.virtualenvs/dailyfresh/local/lib/python3.5/site-packages/django/db/models/sql/query.py", line 1391, in names_to_path
    "Choices are: %s" % (name, ", ".join(available)))
django.core.exceptions.FieldError: Cannot resolve keyword 'user' into field. Choices are: create_time, end_time, founder, id, is_delete, master, master_id, slave, slave_id, update_person, update_time
ERROR 2018-08-22 18:15:44,463 /home/python/.virtualenvs/dailyfresh/local/lib/python3.5/site-packages/django/core/handlers/base.py 256: Internal Server Error: /users/slaves
Traceback (most recent call last):
  File "/home/python/.virtualenvs/dailyfresh/local/lib/python3.5/site-packages/django/db/models/options.py", line 552, in get_field
    return self.fields_map[field_name]
KeyError: 'user'

During handling of the above exception, another exception occurred:

Traceback (most recent call last):
  File "/home/python/.virtualenvs/dailyfresh/local/lib/python3.5/site-packages/django/db/models/sql/query.py", line 1362, in names_to_path
    field = opts.get_field(name)
  File "/home/python/.virtualenvs/dailyfresh/local/lib/python3.5/site-packages/django/db/models/options.py", line 554, in get_field
    raise FieldDoesNotExist('%s has no field named %r' % (self.object_name, field_name))
django.core.exceptions.FieldDoesNotExist: MemberShip has no field named 'user'

During handling of the above exception, another exception occurred:

Traceback (most recent call last):
  File "/home/python/.virtualenvs/dailyfresh/local/lib/python3.5/site-packages/django/core/handlers/base.py", line 132, in get_response
    response = wrapped_callback(request, *callback_args, **callback_kwargs)
  File "/home/python/.virtualenvs/dailyfresh/local/lib/python3.5/site-packages/django/contrib/auth/decorators.py", line 22, in _wrapped_view
    return view_func(request, *args, **kwargs)
  File "/home/python/.virtualenvs/dailyfresh/local/lib/python3.5/site-packages/django/contrib/auth/decorators.py", line 22, in _wrapped_view
    return view_func(request, *args, **kwargs)
  File "/home/python/.virtualenvs/dailyfresh/local/lib/python3.5/site-packages/django/views/generic/base.py", line 71, in view
    return self.dispatch(request, *args, **kwargs)
  File "/home/python/Desktop/Hellocial/Hellocial_0_1/utils/mixin.py", line 93, in dispatch
    return handler(request, *args, **kwargs)
  File "/home/python/Desktop/Hellocial/Hellocial_0_1/apps/users/views.py", line 330, in get
    for slave in rel_page:
  File "/home/python/.virtualenvs/dailyfresh/lib/python3.5/_collections_abc.py", line 815, in __iter__
    v = self[i]
  File "/home/python/.virtualenvs/dailyfresh/local/lib/python3.5/site-packages/django/core/paginator.py", line 125, in __getitem__
    self.object_list = list(self.object_list)
  File "/home/python/.virtualenvs/dailyfresh/local/lib/python3.5/site-packages/django/db/models/query.py", line 162, in __iter__
    self._fetch_all()
  File "/home/python/.virtualenvs/dailyfresh/local/lib/python3.5/site-packages/django/db/models/query.py", line 965, in _fetch_all
    self._result_cache = list(self.iterator())
  File "/home/python/.virtualenvs/dailyfresh/local/lib/python3.5/site-packages/django/db/models/query.py", line 238, in iterator
    results = compiler.execute_sql()
  File "/home/python/.virtualenvs/dailyfresh/local/lib/python3.5/site-packages/django/db/models/sql/compiler.py", line 829, in execute_sql
    sql, params = self.as_sql()
  File "/home/python/.virtualenvs/dailyfresh/local/lib/python3.5/site-packages/django/db/models/sql/compiler.py", line 378, in as_sql
    extra_select, order_by, group_by = self.pre_sql_setup()
  File "/home/python/.virtualenvs/dailyfresh/local/lib/python3.5/site-packages/django/db/models/sql/compiler.py", line 49, in pre_sql_setup
    order_by = self.get_order_by()
  File "/home/python/.virtualenvs/dailyfresh/local/lib/python3.5/site-packages/django/db/models/sql/compiler.py", line 286, in get_order_by
    field, self.query.get_meta(), default_order=asc))
  File "/home/python/.virtualenvs/dailyfresh/local/lib/python3.5/site-packages/django/db/models/sql/compiler.py", line 558, in find_ordering_name
    field, targets, alias, joins, path, opts = self._setup_joins(pieces, opts, alias)
  File "/home/python/.virtualenvs/dailyfresh/local/lib/python3.5/site-packages/django/db/models/sql/compiler.py", line 591, in _setup_joins
    pieces, opts, alias)
  File "/home/python/.virtualenvs/dailyfresh/local/lib/python3.5/site-packages/django/db/models/sql/query.py", line 1466, in setup_joins
    names, opts, allow_many, fail_on_missing=True)
  File "/home/python/.virtualenvs/dailyfresh/local/lib/python3.5/site-packages/django/db/models/sql/query.py", line 1391, in names_to_path
    "Choices are: %s" % (name, ", ".join(available)))
django.core.exceptions.FieldError: Cannot resolve keyword 'user' into field. Choices are: create_time, end_time, founder, id, is_delete, master, master_id, slave, slave_id, update_person, update_time
