ERROR 2018-09-11 14:02:37,876 /home/python/.virtualenvs/dailyfresh/local/lib/python3.5/site-packages/django/core/handlers/base.py 256: Internal Server Error: /
Traceback (most recent call last):
  File "/home/python/.virtualenvs/dailyfresh/local/lib/python3.5/site-packages/django/core/urlresolvers.py", line 394, in urlconf_module
    return self._urlconf_module
AttributeError: 'RegexURLResolver' object has no attribute '_urlconf_module'

During handling of the above exception, another exception occurred:

Traceback (most recent call last):
  File "/home/python/.virtualenvs/dailyfresh/local/lib/python3.5/site-packages/django/core/handlers/base.py", line 119, in get_response
    resolver_match = resolver.resolve(request.path_info)
  File "/home/python/.virtualenvs/dailyfresh/local/lib/python3.5/site-packages/django/core/urlresolvers.py", line 366, in resolve
    for pattern in self.url_patterns:
  File "/home/python/.virtualenvs/dailyfresh/local/lib/python3.5/site-packages/django/core/urlresolvers.py", line 402, in url_patterns
    patterns = getattr(self.urlconf_module, "urlpatterns", self.urlconf_module)
  File "/home/python/.virtualenvs/dailyfresh/local/lib/python3.5/site-packages/django/core/urlresolvers.py", line 396, in urlconf_module
    self._urlconf_module = import_module(self.urlconf_name)
  File "/home/python/.virtualenvs/dailyfresh/lib/python3.5/importlib/__init__.py", line 126, in import_module
    return _bootstrap._gcd_import(name[level:], package, level)
  File "<frozen importlib._bootstrap>", line 986, in _gcd_import
  File "<frozen importlib._bootstrap>", line 969, in _find_and_load
  File "<frozen importlib._bootstrap>", line 958, in _find_and_load_unlocked
  File "<frozen importlib._bootstrap>", line 673, in _load_unlocked
  File "<frozen importlib._bootstrap_external>", line 665, in exec_module
  File "<frozen importlib._bootstrap>", line 222, in _call_with_frames_removed
  File "/home/python/Desktop/Hellocial/Hellocial_0_1/Hellocial_0_1/urls.py", line 19, in <module>
    from apps.users.views import SearchResultView
  File "/home/python/Desktop/Hellocial/Hellocial_0_1/apps/users/views.py", line 21, in <module>
    from tel_apps.gen_script import GenTask
ImportError: No module named 'tel_apps'
ERROR 2018-09-11 14:02:39,474 /home/python/.virtualenvs/dailyfresh/local/lib/python3.5/site-packages/django/core/handlers/base.py 256: Internal Server Error: /favicon.ico
Traceback (most recent call last):
  File "/home/python/.virtualenvs/dailyfresh/local/lib/python3.5/site-packages/django/core/urlresolvers.py", line 394, in urlconf_module
    return self._urlconf_module
AttributeError: 'RegexURLResolver' object has no attribute '_urlconf_module'

During handling of the above exception, another exception occurred:

Traceback (most recent call last):
  File "/home/python/.virtualenvs/dailyfresh/local/lib/python3.5/site-packages/django/core/handlers/base.py", line 108, in get_response
    response = middleware_method(request)
  File "/home/python/.virtualenvs/dailyfresh/local/lib/python3.5/site-packages/django/middleware/common.py", line 74, in process_request
    if (not urlresolvers.is_valid_path(request.path_info, urlconf) and
  File "/home/python/.virtualenvs/dailyfresh/local/lib/python3.5/site-packages/django/core/urlresolvers.py", line 647, in is_valid_path
    resolve(path, urlconf)
  File "/home/python/.virtualenvs/dailyfresh/local/lib/python3.5/site-packages/django/core/urlresolvers.py", line 522, in resolve
    return get_resolver(urlconf).resolve(path)
  File "/home/python/.virtualenvs/dailyfresh/local/lib/python3.5/site-packages/django/core/urlresolvers.py", line 366, in resolve
    for pattern in self.url_patterns:
  File "/home/python/.virtualenvs/dailyfresh/local/lib/python3.5/site-packages/django/core/urlresolvers.py", line 402, in url_patterns
    patterns = getattr(self.urlconf_module, "urlpatterns", self.urlconf_module)
  File "/home/python/.virtualenvs/dailyfresh/local/lib/python3.5/site-packages/django/core/urlresolvers.py", line 396, in urlconf_module
    self._urlconf_module = import_module(self.urlconf_name)
  File "/home/python/.virtualenvs/dailyfresh/lib/python3.5/importlib/__init__.py", line 126, in import_module
    return _bootstrap._gcd_import(name[level:], package, level)
  File "<frozen importlib._bootstrap>", line 986, in _gcd_import
  File "<frozen importlib._bootstrap>", line 969, in _find_and_load
  File "<frozen importlib._bootstrap>", line 958, in _find_and_load_unlocked
  File "<frozen importlib._bootstrap>", line 673, in _load_unlocked
  File "<frozen importlib._bootstrap_external>", line 665, in exec_module
  File "<frozen importlib._bootstrap>", line 222, in _call_with_frames_removed
  File "/home/python/Desktop/Hellocial/Hellocial_0_1/Hellocial_0_1/urls.py", line 19, in <module>
    from apps.users.views import SearchResultView
  File "/home/python/Desktop/Hellocial/Hellocial_0_1/apps/users/views.py", line 21, in <module>
    from tel_apps.gen_script import GenTask
ImportError: No module named 'tel_apps'
ERROR 2018-09-11 14:03:05,242 /home/python/.virtualenvs/dailyfresh/local/lib/python3.5/site-packages/django/core/handlers/base.py 256: Internal Server Error: /
Traceback (most recent call last):
  File "/home/python/.virtualenvs/dailyfresh/local/lib/python3.5/site-packages/django/core/urlresolvers.py", line 394, in urlconf_module
    return self._urlconf_module
AttributeError: 'RegexURLResolver' object has no attribute '_urlconf_module'

During handling of the above exception, another exception occurred:

Traceback (most recent call last):
  File "/home/python/.virtualenvs/dailyfresh/local/lib/python3.5/site-packages/django/core/handlers/base.py", line 119, in get_response
    resolver_match = resolver.resolve(request.path_info)
  File "/home/python/.virtualenvs/dailyfresh/local/lib/python3.5/site-packages/django/core/urlresolvers.py", line 366, in resolve
    for pattern in self.url_patterns:
  File "/home/python/.virtualenvs/dailyfresh/local/lib/python3.5/site-packages/django/core/urlresolvers.py", line 402, in url_patterns
    patterns = getattr(self.urlconf_module, "urlpatterns", self.urlconf_module)
  File "/home/python/.virtualenvs/dailyfresh/local/lib/python3.5/site-packages/django/core/urlresolvers.py", line 396, in urlconf_module
    self._urlconf_module = import_module(self.urlconf_name)
  File "/home/python/.virtualenvs/dailyfresh/lib/python3.5/importlib/__init__.py", line 126, in import_module
    return _bootstrap._gcd_import(name[level:], package, level)
  File "<frozen importlib._bootstrap>", line 986, in _gcd_import
  File "<frozen importlib._bootstrap>", line 969, in _find_and_load
  File "<frozen importlib._bootstrap>", line 958, in _find_and_load_unlocked
  File "<frozen importlib._bootstrap>", line 673, in _load_unlocked
  File "<frozen importlib._bootstrap_external>", line 665, in exec_module
  File "<frozen importlib._bootstrap>", line 222, in _call_with_frames_removed
  File "/home/python/Desktop/Hellocial/Hellocial_0_1/Hellocial_0_1/urls.py", line 24, in <module>
    url(r'^users/',include('apps.users.urls')),
  File "/home/python/.virtualenvs/dailyfresh/local/lib/python3.5/site-packages/django/conf/urls/__init__.py", line 33, in include
    urlconf_module = import_module(urlconf_module)
  File "/home/python/.virtualenvs/dailyfresh/lib/python3.5/importlib/__init__.py", line 126, in import_module
    return _bootstrap._gcd_import(name[level:], package, level)
  File "<frozen importlib._bootstrap>", line 986, in _gcd_import
  File "<frozen importlib._bootstrap>", line 969, in _find_and_load
  File "<frozen importlib._bootstrap>", line 958, in _find_and_load_unlocked
  File "<frozen importlib._bootstrap>", line 673, in _load_unlocked
  File "<frozen importlib._bootstrap_external>", line 665, in exec_module
  File "<frozen importlib._bootstrap>", line 222, in _call_with_frames_removed
  File "/home/python/Desktop/Hellocial/Hellocial_0_1/apps/users/urls.py", line 17, in <module>
    from apps.users.views import UserInfoView, CheckCodeView, LoginView, LoginOutView, RegisterView, UserRelationView, \
ImportError: cannot import name 'PhoneAppLoginView'
ERROR 2018-09-11 14:03:06,375 /home/python/.virtualenvs/dailyfresh/local/lib/python3.5/site-packages/django/core/handlers/base.py 256: Internal Server Error: /favicon.ico
Traceback (most recent call last):
  File "/home/python/.virtualenvs/dailyfresh/local/lib/python3.5/site-packages/django/core/urlresolvers.py", line 394, in urlconf_module
    return self._urlconf_module
AttributeError: 'RegexURLResolver' object has no attribute '_urlconf_module'

During handling of the above exception, another exception occurred:

Traceback (most recent call last):
  File "/home/python/.virtualenvs/dailyfresh/local/lib/python3.5/site-packages/django/core/handlers/base.py", line 108, in get_response
    response = middleware_method(request)
  File "/home/python/.virtualenvs/dailyfresh/local/lib/python3.5/site-packages/django/middleware/common.py", line 74, in process_request
    if (not urlresolvers.is_valid_path(request.path_info, urlconf) and
  File "/home/python/.virtualenvs/dailyfresh/local/lib/python3.5/site-packages/django/core/urlresolvers.py", line 647, in is_valid_path
    resolve(path, urlconf)
  File "/home/python/.virtualenvs/dailyfresh/local/lib/python3.5/site-packages/django/core/urlresolvers.py", line 522, in resolve
    return get_resolver(urlconf).resolve(path)
  File "/home/python/.virtualenvs/dailyfresh/local/lib/python3.5/site-packages/django/core/urlresolvers.py", line 366, in resolve
    for pattern in self.url_patterns:
  File "/home/python/.virtualenvs/dailyfresh/local/lib/python3.5/site-packages/django/core/urlresolvers.py", line 402, in url_patterns
    patterns = getattr(self.urlconf_module, "urlpatterns", self.urlconf_module)
  File "/home/python/.virtualenvs/dailyfresh/local/lib/python3.5/site-packages/django/core/urlresolvers.py", line 396, in urlconf_module
    self._urlconf_module = import_module(self.urlconf_name)
  File "/home/python/.virtualenvs/dailyfresh/lib/python3.5/importlib/__init__.py", line 126, in import_module
    return _bootstrap._gcd_import(name[level:], package, level)
  File "<frozen importlib._bootstrap>", line 986, in _gcd_import
  File "<frozen importlib._bootstrap>", line 969, in _find_and_load
  File "<frozen importlib._bootstrap>", line 958, in _find_and_load_unlocked
  File "<frozen importlib._bootstrap>", line 673, in _load_unlocked
  File "<frozen importlib._bootstrap_external>", line 665, in exec_module
  File "<frozen importlib._bootstrap>", line 222, in _call_with_frames_removed
  File "/home/python/Desktop/Hellocial/Hellocial_0_1/Hellocial_0_1/urls.py", line 24, in <module>
    url(r'^users/',include('apps.users.urls')),
  File "/home/python/.virtualenvs/dailyfresh/local/lib/python3.5/site-packages/django/conf/urls/__init__.py", line 33, in include
    urlconf_module = import_module(urlconf_module)
  File "/home/python/.virtualenvs/dailyfresh/lib/python3.5/importlib/__init__.py", line 126, in import_module
    return _bootstrap._gcd_import(name[level:], package, level)
  File "<frozen importlib._bootstrap>", line 986, in _gcd_import
  File "<frozen importlib._bootstrap>", line 969, in _find_and_load
  File "<frozen importlib._bootstrap>", line 958, in _find_and_load_unlocked
  File "<frozen importlib._bootstrap>", line 673, in _load_unlocked
  File "<frozen importlib._bootstrap_external>", line 665, in exec_module
  File "<frozen importlib._bootstrap>", line 222, in _call_with_frames_removed
  File "/home/python/Desktop/Hellocial/Hellocial_0_1/apps/users/urls.py", line 17, in <module>
    from apps.users.views import UserInfoView, CheckCodeView, LoginView, LoginOutView, RegisterView, UserRelationView, \
ImportError: cannot import name 'PhoneAppLoginView'
ERROR 2018-09-11 14:03:08,862 /home/python/.virtualenvs/dailyfresh/local/lib/python3.5/site-packages/django/core/handlers/base.py 256: Internal Server Error: /
Traceback (most recent call last):
  File "/home/python/.virtualenvs/dailyfresh/local/lib/python3.5/site-packages/django/core/urlresolvers.py", line 394, in urlconf_module
    return self._urlconf_module
AttributeError: 'RegexURLResolver' object has no attribute '_urlconf_module'

During handling of the above exception, another exception occurred:

Traceback (most recent call last):
  File "/home/python/.virtualenvs/dailyfresh/local/lib/python3.5/site-packages/django/core/handlers/base.py", line 119, in get_response
    resolver_match = resolver.resolve(request.path_info)
  File "/home/python/.virtualenvs/dailyfresh/local/lib/python3.5/site-packages/django/core/urlresolvers.py", line 366, in resolve
    for pattern in self.url_patterns:
  File "/home/python/.virtualenvs/dailyfresh/local/lib/python3.5/site-packages/django/core/urlresolvers.py", line 402, in url_patterns
    patterns = getattr(self.urlconf_module, "urlpatterns", self.urlconf_module)
  File "/home/python/.virtualenvs/dailyfresh/local/lib/python3.5/site-packages/django/core/urlresolvers.py", line 396, in urlconf_module
    self._urlconf_module = import_module(self.urlconf_name)
  File "/home/python/.virtualenvs/dailyfresh/lib/python3.5/importlib/__init__.py", line 126, in import_module
    return _bootstrap._gcd_import(name[level:], package, level)
  File "<frozen importlib._bootstrap>", line 986, in _gcd_import
  File "<frozen importlib._bootstrap>", line 969, in _find_and_load
  File "<frozen importlib._bootstrap>", line 958, in _find_and_load_unlocked
  File "<frozen importlib._bootstrap>", line 673, in _load_unlocked
  File "<frozen importlib._bootstrap_external>", line 665, in exec_module
  File "<frozen importlib._bootstrap>", line 222, in _call_with_frames_removed
  File "/home/python/Desktop/Hellocial/Hellocial_0_1/Hellocial_0_1/urls.py", line 24, in <module>
    url(r'^users/',include('apps.users.urls')),
  File "/home/python/.virtualenvs/dailyfresh/local/lib/python3.5/site-packages/django/conf/urls/__init__.py", line 33, in include
    urlconf_module = import_module(urlconf_module)
  File "/home/python/.virtualenvs/dailyfresh/lib/python3.5/importlib/__init__.py", line 126, in import_module
    return _bootstrap._gcd_import(name[level:], package, level)
  File "<frozen importlib._bootstrap>", line 986, in _gcd_import
  File "<frozen importlib._bootstrap>", line 969, in _find_and_load
  File "<frozen importlib._bootstrap>", line 958, in _find_and_load_unlocked
  File "<frozen importlib._bootstrap>", line 673, in _load_unlocked
  File "<frozen importlib._bootstrap_external>", line 665, in exec_module
  File "<frozen importlib._bootstrap>", line 222, in _call_with_frames_removed
  File "/home/python/Desktop/Hellocial/Hellocial_0_1/apps/users/urls.py", line 17, in <module>
    from apps.users.views import UserInfoView, CheckCodeView, LoginView, LoginOutView, RegisterView, UserRelationView, \
ImportError: cannot import name 'PhoneAppLoginView'
ERROR 2018-09-11 14:03:09,182 /home/python/.virtualenvs/dailyfresh/local/lib/python3.5/site-packages/django/core/handlers/base.py 256: Internal Server Error: /favicon.ico
Traceback (most recent call last):
  File "/home/python/.virtualenvs/dailyfresh/local/lib/python3.5/site-packages/django/core/urlresolvers.py", line 394, in urlconf_module
    return self._urlconf_module
AttributeError: 'RegexURLResolver' object has no attribute '_urlconf_module'

During handling of the above exception, another exception occurred:

Traceback (most recent call last):
  File "/home/python/.virtualenvs/dailyfresh/local/lib/python3.5/site-packages/django/core/handlers/base.py", line 108, in get_response
    response = middleware_method(request)
  File "/home/python/.virtualenvs/dailyfresh/local/lib/python3.5/site-packages/django/middleware/common.py", line 74, in process_request
    if (not urlresolvers.is_valid_path(request.path_info, urlconf) and
  File "/home/python/.virtualenvs/dailyfresh/local/lib/python3.5/site-packages/django/core/urlresolvers.py", line 647, in is_valid_path
    resolve(path, urlconf)
  File "/home/python/.virtualenvs/dailyfresh/local/lib/python3.5/site-packages/django/core/urlresolvers.py", line 522, in resolve
    return get_resolver(urlconf).resolve(path)
  File "/home/python/.virtualenvs/dailyfresh/local/lib/python3.5/site-packages/django/core/urlresolvers.py", line 366, in resolve
    for pattern in self.url_patterns:
  File "/home/python/.virtualenvs/dailyfresh/local/lib/python3.5/site-packages/django/core/urlresolvers.py", line 402, in url_patterns
    patterns = getattr(self.urlconf_module, "urlpatterns", self.urlconf_module)
  File "/home/python/.virtualenvs/dailyfresh/local/lib/python3.5/site-packages/django/core/urlresolvers.py", line 396, in urlconf_module
    self._urlconf_module = import_module(self.urlconf_name)
  File "/home/python/.virtualenvs/dailyfresh/lib/python3.5/importlib/__init__.py", line 126, in import_module
    return _bootstrap._gcd_import(name[level:], package, level)
  File "<frozen importlib._bootstrap>", line 986, in _gcd_import
  File "<frozen importlib._bootstrap>", line 969, in _find_and_load
  File "<frozen importlib._bootstrap>", line 958, in _find_and_load_unlocked
  File "<frozen importlib._bootstrap>", line 673, in _load_unlocked
  File "<frozen importlib._bootstrap_external>", line 665, in exec_module
  File "<frozen importlib._bootstrap>", line 222, in _call_with_frames_removed
  File "/home/python/Desktop/Hellocial/Hellocial_0_1/Hellocial_0_1/urls.py", line 24, in <module>
    url(r'^users/',include('apps.users.urls')),
  File "/home/python/.virtualenvs/dailyfresh/local/lib/python3.5/site-packages/django/conf/urls/__init__.py", line 33, in include
    urlconf_module = import_module(urlconf_module)
  File "/home/python/.virtualenvs/dailyfresh/lib/python3.5/importlib/__init__.py", line 126, in import_module
    return _bootstrap._gcd_import(name[level:], package, level)
  File "<frozen importlib._bootstrap>", line 986, in _gcd_import
  File "<frozen importlib._bootstrap>", line 969, in _find_and_load
  File "<frozen importlib._bootstrap>", line 958, in _find_and_load_unlocked
  File "<frozen importlib._bootstrap>", line 673, in _load_unlocked
  File "<frozen importlib._bootstrap_external>", line 665, in exec_module
  File "<frozen importlib._bootstrap>", line 222, in _call_with_frames_removed
  File "/home/python/Desktop/Hellocial/Hellocial_0_1/apps/users/urls.py", line 17, in <module>
    from apps.users.views import UserInfoView, CheckCodeView, LoginView, LoginOutView, RegisterView, UserRelationView, \
ImportError: cannot import name 'PhoneAppLoginView'
WARNING 2018-09-11 14:03:33,317 /home/python/.virtualenvs/dailyfresh/local/lib/python3.5/site-packages/django/core/handlers/base.py 170: Not Found: /
WARNING 2018-09-11 14:03:33,377 /home/python/.virtualenvs/dailyfresh/local/lib/python3.5/site-packages/django/core/handlers/base.py 170: Not Found: /favicon.ico
WARNING 2018-09-11 14:04:11,636 /home/python/Desktop/Hellocial/Hellocial_0_1/apps/users/views.py 1039: 用户缺乏隶属信息
WARNING 2018-09-11 14:13:30,761 /home/python/Desktop/Hellocial/Hellocial_0_1/apps/users/views.py 1039: 用户缺乏隶属信息
WARNING 2018-09-11 14:33:51,298 /home/python/Desktop/Hellocial/Hellocial_0_1/apps/users/views.py 680: 代理商企图修改截止时间,修改人id为:1
WARNING 2018-09-11 14:34:03,716 /home/python/Desktop/Hellocial/Hellocial_0_1/apps/users/views.py 680: 代理商企图修改截止时间,修改人id为:1
WARNING 2018-09-11 14:34:59,328 /home/python/Desktop/Hellocial/Hellocial_0_1/apps/users/views.py 680: 代理商企图修改截止时间,修改人id为:1
WARNING 2018-09-11 14:35:06,955 /home/python/Desktop/Hellocial/Hellocial_0_1/apps/users/views.py 680: 代理商企图修改截止时间,修改人id为:1
WARNING 2018-09-11 14:35:14,245 /home/python/Desktop/Hellocial/Hellocial_0_1/apps/users/views.py 680: 代理商企图修改截止时间,修改人id为:1
WARNING 2018-09-11 14:35:22,950 /home/python/Desktop/Hellocial/Hellocial_0_1/apps/users/views.py 680: 代理商企图修改截止时间,修改人id为:1
WARNING 2018-09-11 14:35:30,977 /home/python/Desktop/Hellocial/Hellocial_0_1/apps/users/views.py 680: 代理商企图修改截止时间,修改人id为:1
WARNING 2018-09-11 14:56:41,429 /home/python/Desktop/Hellocial/Hellocial_0_1/apps/users/views.py 684: 代理商企图修改截止时间,修改人id为:1
WARNING 2018-09-11 14:57:22,516 /home/python/Desktop/Hellocial/Hellocial_0_1/apps/users/views.py 684: 代理商企图修改截止时间,修改人id为:1
WARNING 2018-09-11 14:57:36,242 /home/python/Desktop/Hellocial/Hellocial_0_1/apps/users/views.py 684: 代理商企图修改截止时间,修改人id为:1
WARNING 2018-09-11 15:00:00,782 /home/python/Desktop/Hellocial/Hellocial_0_1/apps/users/views.py 684: 代理商企图修改截止时间,修改人id为:1
WARNING 2018-09-11 15:00:06,758 /home/python/Desktop/Hellocial/Hellocial_0_1/apps/users/views.py 684: 代理商企图修改截止时间,修改人id为:1
WARNING 2018-09-11 15:02:37,355 /home/python/Desktop/Hellocial/Hellocial_0_1/apps/users/views.py 688: 代理商企图修改截止时间,修改人id为:1
WARNING 2018-09-11 15:02:45,246 /home/python/Desktop/Hellocial/Hellocial_0_1/apps/users/views.py 688: 代理商企图修改截止时间,修改人id为:1
WARNING 2018-09-11 15:02:50,681 /home/python/Desktop/Hellocial/Hellocial_0_1/apps/users/views.py 688: 代理商企图修改截止时间,修改人id为:1
WARNING 2018-09-11 15:02:56,471 /home/python/Desktop/Hellocial/Hellocial_0_1/apps/users/views.py 688: 代理商企图修改截止时间,修改人id为:1
WARNING 2018-09-11 15:03:01,700 /home/python/Desktop/Hellocial/Hellocial_0_1/apps/users/views.py 688: 代理商企图修改截止时间,修改人id为:1
WARNING 2018-09-11 15:03:08,270 /home/python/Desktop/Hellocial/Hellocial_0_1/apps/users/views.py 688: 代理商企图修改截止时间,修改人id为:1
WARNING 2018-09-11 15:03:14,008 /home/python/Desktop/Hellocial/Hellocial_0_1/apps/users/views.py 688: 代理商企图修改截止时间,修改人id为:1
WARNING 2018-09-11 15:09:34,574 /home/python/Desktop/Hellocial/Hellocial_0_1/apps/users/views.py 1047: 用户缺乏隶属信息
WARNING 2018-09-11 15:13:06,754 /home/python/Desktop/Hellocial/Hellocial_0_1/apps/users/views.py 688: 代理商企图修改截止时间,修改人id为:1
WARNING 2018-09-11 16:00:56,478 /home/python/Desktop/Hellocial/Hellocial_0_1/apps/users/views.py 688: 代理商企图修改截止时间,修改人id为:1
